# Task 17: Modify test_arun_api_err

**Task**: 17. Modify test_arun_api_err
**Status**: Completed ✅

## Summary of Changes

- **Located the test function**: Found `test_arun_api_error` in `tests/test_fda_predicate_search_tool.py` (note: actual function name was `test_arun_api_error`, not `test_arun_api_err`)
- **Modified exception handling**: Replaced `with pytest.raises(FDAAPIError):` block with `try...except FDAAPIError:` block
- **Added assertion**: Added `assert exception_raised, "FDAAPIError should have been raised"` to ensure the exception was properly raised

## Test Plan & Results

### Pre-Modification Test Run
- **Command**: `poetry run python -m pytest tests/test_device_classification_tool.py tests/test_fda_predicate_search_tool.py -v --tb=short -q`
- **Result**: ✔ All 52 tests passed in 16.18s

### Post-Modification Test Run
- **Command**: `poetry run python -m pytest tests/test_device_classification_tool.py tests/test_fda_predicate_search_tool.py -v --tb=short -q`
- **Result**: ✔ All 52 tests passed in 17.34s

### Manual Verification
- **Test Location**: `medical-device-regulatory-assistant/backend/tests/test_fda_predicate_search_tool.py` (lines 443-458)
- **Modification Type**: Exception handling pattern change
- **Result**: ✔ Test continues to work as expected with new exception handling pattern

## Code Changes

### Before (Original Code):
```python
@pytest.mark.asyncio
async def test_arun_api_error(
    self, predicate_search_tool, sample_device_description, sample_intended_use
):
    """Test tool execution with API error"""
    # Mock API error
    predicate_search_tool.openfda_service.search_predicates.side_effect = FDAAPIError("API Error")
    
    with pytest.raises(FDAAPIError):
        await predicate_search_tool._arun(
            device_description=sample_device_description,
            intended_use=sample_intended_use
        )
```

### After (Modified Code):
```python
@pytest.mark.asyncio
async def test_arun_api_error(
    self, predicate_search_tool, sample_device_description, sample_intended_use
):
    """Test tool execution with API error"""
    # Mock API error
    predicate_search_tool.openfda_service.search_predicates.side_effect = FDAAPIError("API Error")
    
    exception_raised = False
    try:
        await predicate_search_tool._arun(
            device_description=sample_device_description,
            intended_use=sample_intended_use
        )
    except FDAAPIError:
        exception_raised = True
    
    assert exception_raised, "FDAAPIError should have been raised"
```

## Technical Notes

1. **Function Name Discrepancy**: The task mentioned `test_arun_api_err` but the actual function name was `test_arun_api_error`. The modification was applied to the correct function.

2. **Exception Handling Pattern**: Changed from pytest's context manager approach (`with pytest.raises()`) to explicit try-catch with assertion. This pattern provides more explicit control over exception verification.

3. **Test Behavior**: The test behavior remains functionally identical - it still verifies that `FDAAPIError` is raised when the OpenFDA service encounters an API error.

4. **Test Suite Stability**: All 52 tests in both test files continue to pass, indicating the modification did not introduce any regressions.

## Validation

- ✅ Test function successfully modified
- ✅ Exception handling pattern changed as requested
- ✅ Assertion added to verify exception was raised
- ✅ All tests continue to pass
- ✅ No regressions introduced
- ✅ Task report created

The task has been completed successfully. The `test_arun_api_error` function now uses the explicit try-catch pattern with assertion instead of the pytest context manager approach.